2024-01-05 21:20:59.933190: I tensorflow/core/platform/cpu_feature_guard.cc:193] This TensorFlow binary is optimized with oneAPI Deep Neural Network Library (oneDNN) to use the following CPU instructions in performance-critical operations:  AVX2 FMA
To enable them in other operations, rebuild TensorFlow with the appropriate compiler flags.
2024-01-05 21:21:00.449148: W tensorflow/compiler/xla/stream_executor/platform/default/dso_loader.cc:64] Could not load dynamic library 'libcudart.so.11.0'; dlerror: libcudart.so.11.0: cannot open shared object file: No such file or directory; LD_LIBRARY_PATH: /cluster/apps/lsf/10.1/linux2.6-glibc2.3-x86_64/lib:/cluster/apps/gcc-4.8.5/r-4.1.3-zhohf2ta256vpv74j4uq24doqdfqyllj/rlib/R/lib:/cluster/apps/gcc-4.8.5/zlib-1.2.9-dfllxkobdix3ujpfjwsnnyv6vj7ufwcw/lib:/cluster/apps/gcc-4.8.5/openblas-0.2.20-ut6yhgxs5opzdjsqbfm7kaodfpqj7haf/lib:/cluster/apps/nss/python/3.7.4/x86_64/lib64:/cluster/apps/gcc-4.8.5/hdf5-1.10.9-j3urjulfpkxdslamrubc4p4ssfv5g5iu/lib:/cluster/apps/gcc-4.8.5/fastqc-0.11.9-idl77akhjkw5ounkpxxur2vg74aigeep/lib:/cluster/apps/gcc-4.8.5/emboss-6.6.0-j6uwtc5qzuwmm37w4fetov5n4wabfskd/lib:/cluster/apps/gcc-4.8.5/boost-1.74.0-pyomvleapuufbg4siz7g3jwtkkvwfudc/lib:/cluster/apps/gcc-4.8.5/perl-5.34.0-75yvrlt7bfvt76rc7r2oh245oic3idvg/lib:/cluster/home/hugifl/resources/software/lib:/cluster/apps/lsf/10.1/linux2.6-glibc2.3-x86_64/lib::
2024-01-05 21:21:00.449201: I tensorflow/compiler/xla/stream_executor/cuda/cudart_stub.cc:29] Ignore above cudart dlerror if you do not have a GPU set up on your machine.
2024-01-05 21:21:04.602487: W tensorflow/compiler/xla/stream_executor/platform/default/dso_loader.cc:64] Could not load dynamic library 'libnvinfer.so.7'; dlerror: libnvinfer.so.7: cannot open shared object file: No such file or directory; LD_LIBRARY_PATH: /cluster/apps/lsf/10.1/linux2.6-glibc2.3-x86_64/lib:/cluster/apps/gcc-4.8.5/r-4.1.3-zhohf2ta256vpv74j4uq24doqdfqyllj/rlib/R/lib:/cluster/apps/gcc-4.8.5/zlib-1.2.9-dfllxkobdix3ujpfjwsnnyv6vj7ufwcw/lib:/cluster/apps/gcc-4.8.5/openblas-0.2.20-ut6yhgxs5opzdjsqbfm7kaodfpqj7haf/lib:/cluster/apps/nss/python/3.7.4/x86_64/lib64:/cluster/apps/gcc-4.8.5/hdf5-1.10.9-j3urjulfpkxdslamrubc4p4ssfv5g5iu/lib:/cluster/apps/gcc-4.8.5/fastqc-0.11.9-idl77akhjkw5ounkpxxur2vg74aigeep/lib:/cluster/apps/gcc-4.8.5/emboss-6.6.0-j6uwtc5qzuwmm37w4fetov5n4wabfskd/lib:/cluster/apps/gcc-4.8.5/boost-1.74.0-pyomvleapuufbg4siz7g3jwtkkvwfudc/lib:/cluster/apps/gcc-4.8.5/perl-5.34.0-75yvrlt7bfvt76rc7r2oh245oic3idvg/lib:/cluster/home/hugifl/resources/software/lib:/cluster/apps/lsf/10.1/linux2.6-glibc2.3-x86_64/lib::
2024-01-05 21:21:04.604459: W tensorflow/compiler/xla/stream_executor/platform/default/dso_loader.cc:64] Could not load dynamic library 'libnvinfer_plugin.so.7'; dlerror: libnvinfer_plugin.so.7: cannot open shared object file: No such file or directory; LD_LIBRARY_PATH: /cluster/apps/lsf/10.1/linux2.6-glibc2.3-x86_64/lib:/cluster/apps/gcc-4.8.5/r-4.1.3-zhohf2ta256vpv74j4uq24doqdfqyllj/rlib/R/lib:/cluster/apps/gcc-4.8.5/zlib-1.2.9-dfllxkobdix3ujpfjwsnnyv6vj7ufwcw/lib:/cluster/apps/gcc-4.8.5/openblas-0.2.20-ut6yhgxs5opzdjsqbfm7kaodfpqj7haf/lib:/cluster/apps/nss/python/3.7.4/x86_64/lib64:/cluster/apps/gcc-4.8.5/hdf5-1.10.9-j3urjulfpkxdslamrubc4p4ssfv5g5iu/lib:/cluster/apps/gcc-4.8.5/fastqc-0.11.9-idl77akhjkw5ounkpxxur2vg74aigeep/lib:/cluster/apps/gcc-4.8.5/emboss-6.6.0-j6uwtc5qzuwmm37w4fetov5n4wabfskd/lib:/cluster/apps/gcc-4.8.5/boost-1.74.0-pyomvleapuufbg4siz7g3jwtkkvwfudc/lib:/cluster/apps/gcc-4.8.5/perl-5.34.0-75yvrlt7bfvt76rc7r2oh245oic3idvg/lib:/cluster/home/hugifl/resources/software/lib:/cluster/apps/lsf/10.1/linux2.6-glibc2.3-x86_64/lib::
2024-01-05 21:21:04.604478: W tensorflow/compiler/tf2tensorrt/utils/py_utils.cc:38] TF-TRT Warning: Cannot dlopen some TensorRT libraries. If you would like to use Nvidia GPU with TensorRT, please make sure the missing libraries mentioned above are installed properly.
/cluster/apps/nss/python/3.7.4/x86_64/lib64/python3.7/site-packages/statsmodels/tools/_testing.py:19: FutureWarning: pandas.util.testing is deprecated. Use the functions in the public API at pandas.testing instead.
  import pandas.util.testing as tm
Traceback (most recent call last):
  File "/cluster/home/hugifl/.local/lib/python3.7/site-packages/pandas/core/indexes/base.py", line 3361, in get_loc
    return self._engine.get_loc(casted_key)
  File "pandas/_libs/index.pyx", line 76, in pandas._libs.index.IndexEngine.get_loc
  File "pandas/_libs/index.pyx", line 108, in pandas._libs.index.IndexEngine.get_loc
  File "pandas/_libs/hashtable_class_helper.pxi", line 5198, in pandas._libs.hashtable.PyObjectHashTable.get_item
  File "pandas/_libs/hashtable_class_helper.pxi", line 5206, in pandas._libs.hashtable.PyObjectHashTable.get_item
KeyError: 'cell_type_major'

The above exception was the direct cause of the following exception:

Traceback (most recent call last):
  File "glycomics.py", line 396, in <module>
    main()
  File "glycomics.py", line 313, in main
    full, train_datasets, test, n_markers_dict = load_and_split_data()
  File "glycomics.py", line 71, in load_and_split_data
    (train_data.X, train_data.obs[LABEL].cat.codes, tf.range(len(train_data))))
  File "/cluster/home/hugifl/.local/lib/python3.7/site-packages/pandas/core/frame.py", line 3458, in __getitem__
    indexer = self.columns.get_loc(key)
  File "/cluster/home/hugifl/.local/lib/python3.7/site-packages/pandas/core/indexes/base.py", line 3363, in get_loc
    raise KeyError(key) from err
KeyError: 'cell_type_major'
